[2024-05-31T14:53:36.557+0000] {local_task_job_runner.py:120} INFO - ::group::Pre task execution logs
[2024-05-31T14:53:36.585+0000] {taskinstance.py:2076} INFO - Dependencies all met for dep_context=non-requeueable deps ti=<TaskInstance: ingestion_data.insertar_datos scheduled__2024-05-30T00:00:00+00:00 [queued]>
[2024-05-31T14:53:36.598+0000] {taskinstance.py:2076} INFO - Dependencies all met for dep_context=requeueable deps ti=<TaskInstance: ingestion_data.insertar_datos scheduled__2024-05-30T00:00:00+00:00 [queued]>
[2024-05-31T14:53:36.599+0000] {taskinstance.py:2306} INFO - Starting attempt 2 of 2
[2024-05-31T14:53:36.617+0000] {taskinstance.py:2330} INFO - Executing <Task(PythonOperator): insertar_datos> on 2024-05-30 00:00:00+00:00
[2024-05-31T14:53:36.625+0000] {standard_task_runner.py:63} INFO - Started process 418 to run task
[2024-05-31T14:53:36.629+0000] {standard_task_runner.py:90} INFO - Running: ['***', 'tasks', 'run', 'ingestion_data', 'insertar_datos', 'scheduled__2024-05-30T00:00:00+00:00', '--job-id', '41', '--raw', '--subdir', 'DAGS_FOLDER/dag_entregable_fedebar.py', '--cfg-path', '/tmp/tmphk11la3l']
[2024-05-31T14:53:36.631+0000] {standard_task_runner.py:91} INFO - Job 41: Subtask insertar_datos
[2024-05-31T14:53:36.681+0000] {task_command.py:426} INFO - Running <TaskInstance: ingestion_data.insertar_datos scheduled__2024-05-30T00:00:00+00:00 [running]> on host 167cb9f6b96a
[2024-05-31T14:53:36.760+0000] {taskinstance.py:2648} INFO - Exporting env vars: AIRFLOW_CTX_DAG_OWNER='FedeBar' AIRFLOW_CTX_DAG_ID='ingestion_data' AIRFLOW_CTX_TASK_ID='insertar_datos' AIRFLOW_CTX_EXECUTION_DATE='2024-05-30T00:00:00+00:00' AIRFLOW_CTX_TRY_NUMBER='2' AIRFLOW_CTX_DAG_RUN_ID='scheduled__2024-05-30T00:00:00+00:00'
[2024-05-31T14:53:36.761+0000] {taskinstance.py:430} INFO - ::endgroup::
[2024-05-31T14:53:36.770+0000] {base.py:84} INFO - Using connection ID 'coder-redshift-fede' for task execution.
[2024-05-31T14:53:36.771+0000] {weather_info_ETL.py:15} INFO - Conectando a Redshift en data-engineer-cluster.cyhh5bfevlmn.us-east-1.redshift.amazonaws.com:5439/data-engineer-database
[2024-05-31T14:53:38.276+0000] {warnings.py:109} WARNING - /opt/***/dags/weather_info_ETL.py:150: UserWarning: pandas only supports SQLAlchemy connectable (engine/connection) or database string URI or sqlite3 DBAPI2 connection. Other DBAPI2 objects are not tested. Please consider using SQLAlchemy.
  existing_data = pd.read_sql(query_existing_data, conn)

[2024-05-31T14:53:38.983+0000] {warnings.py:109} WARNING - /opt/***/dags/weather_info_ETL.py:154: UserWarning: pandas only supports SQLAlchemy connectable (engine/connection) or database string URI or sqlite3 DBAPI2 connection. Other DBAPI2 objects are not tested. Please consider using SQLAlchemy.
  max_existing_load_date = pd.read_sql(query_max_load_date, conn).iloc[0, 0]

[2024-05-31T14:53:39.161+0000] {taskinstance.py:441} INFO - ::group::Post task execution logs
[2024-05-31T14:53:39.162+0000] {taskinstance.py:2905} ERROR - Task failed with exception
Traceback (most recent call last):
  File "/home/airflow/.local/lib/python3.8/site-packages/airflow/models/taskinstance.py", line 465, in _execute_task
    result = _execute_callable(context=context, **execute_callable_kwargs)
  File "/home/airflow/.local/lib/python3.8/site-packages/airflow/models/taskinstance.py", line 432, in _execute_callable
    return execute_callable(context=context, **execute_callable_kwargs)
  File "/home/airflow/.local/lib/python3.8/site-packages/airflow/models/baseoperator.py", line 400, in wrapper
    return func(self, *args, **kwargs)
  File "/home/airflow/.local/lib/python3.8/site-packages/airflow/operators/python.py", line 235, in execute
    return_value = self.execute_callable()
  File "/home/airflow/.local/lib/python3.8/site-packages/airflow/operators/python.py", line 252, in execute_callable
    return self.python_callable(*self.op_args, **self.op_kwargs)
  File "/opt/airflow/dags/weather_info_ETL.py", line 156, in insertar_data
    max_daily_load_date = completed_dataframe['load_date'].max()
NameError: name 'completed_dataframe' is not defined
[2024-05-31T14:53:39.174+0000] {taskinstance.py:1206} INFO - Marking task as FAILED. dag_id=ingestion_data, task_id=insertar_datos, run_id=scheduled__2024-05-30T00:00:00+00:00, execution_date=20240530T000000, start_date=20240531T145336, end_date=20240531T145339
[2024-05-31T14:53:39.190+0000] {standard_task_runner.py:110} ERROR - Failed to execute job 41 for task insertar_datos (name 'completed_dataframe' is not defined; 418)
[2024-05-31T14:53:39.214+0000] {local_task_job_runner.py:240} INFO - Task exited with return code 1
[2024-05-31T14:53:39.232+0000] {taskinstance.py:3498} INFO - 0 downstream tasks scheduled from follow-on schedule check
[2024-05-31T14:53:39.235+0000] {local_task_job_runner.py:222} INFO - ::endgroup::
