[2024-05-21T01:08:17.228+0000] {local_task_job_runner.py:120} INFO - ::group::Pre task execution logs
[2024-05-21T01:08:17.318+0000] {taskinstance.py:2076} INFO - Dependencies all met for dep_context=non-requeueable deps ti=<TaskInstance: Preentrega3-fedebar.main scheduled__2024-05-20T20:00:00+00:00 [queued]>
[2024-05-21T01:08:17.346+0000] {taskinstance.py:2076} INFO - Dependencies all met for dep_context=requeueable deps ti=<TaskInstance: Preentrega3-fedebar.main scheduled__2024-05-20T20:00:00+00:00 [queued]>
[2024-05-21T01:08:17.351+0000] {taskinstance.py:2306} INFO - Starting attempt 2 of 2
[2024-05-21T01:08:17.434+0000] {taskinstance.py:2330} INFO - Executing <Task(PythonOperator): main> on 2024-05-20 20:00:00+00:00
[2024-05-21T01:08:17.469+0000] {standard_task_runner.py:63} INFO - Started process 998 to run task
[2024-05-21T01:08:17.499+0000] {standard_task_runner.py:90} INFO - Running: ['***', 'tasks', 'run', 'Preentrega3-fedebar', 'main', 'scheduled__2024-05-20T20:00:00+00:00', '--job-id', '21', '--raw', '--subdir', 'DAGS_FOLDER/dags_python_fedebar.py', '--cfg-path', '/tmp/tmpiom8ngm6']
[2024-05-21T01:08:17.502+0000] {standard_task_runner.py:91} INFO - Job 21: Subtask main
[2024-05-21T01:08:17.900+0000] {task_command.py:426} INFO - Running <TaskInstance: Preentrega3-fedebar.main scheduled__2024-05-20T20:00:00+00:00 [running]> on host ab7b4a79fe7d
[2024-05-21T01:08:18.273+0000] {taskinstance.py:2648} INFO - Exporting env vars: AIRFLOW_CTX_DAG_OWNER='FedeBar' AIRFLOW_CTX_DAG_ID='Preentrega3-fedebar' AIRFLOW_CTX_TASK_ID='main' AIRFLOW_CTX_EXECUTION_DATE='2024-05-20T20:00:00+00:00' AIRFLOW_CTX_TRY_NUMBER='2' AIRFLOW_CTX_DAG_RUN_ID='scheduled__2024-05-20T20:00:00+00:00'
[2024-05-21T01:08:18.286+0000] {taskinstance.py:430} INFO - ::endgroup::
[2024-05-21T01:08:18.289+0000] {logging_mixin.py:188} INFO - Inicio: 2024-05-21 01:08:18.289436
[2024-05-21T01:08:18.292+0000] {taskinstance.py:441} INFO - ::group::Post task execution logs
[2024-05-21T01:08:18.303+0000] {taskinstance.py:2905} ERROR - Task failed with exception
Traceback (most recent call last):
  File "/home/airflow/.local/lib/python3.8/site-packages/airflow/models/taskinstance.py", line 465, in _execute_task
    result = _execute_callable(context=context, **execute_callable_kwargs)
  File "/home/airflow/.local/lib/python3.8/site-packages/airflow/models/taskinstance.py", line 432, in _execute_callable
    return execute_callable(context=context, **execute_callable_kwargs)
  File "/home/airflow/.local/lib/python3.8/site-packages/airflow/models/baseoperator.py", line 400, in wrapper
    return func(self, *args, **kwargs)
  File "/home/airflow/.local/lib/python3.8/site-packages/airflow/operators/python.py", line 235, in execute
    return_value = self.execute_callable()
  File "/home/airflow/.local/lib/python3.8/site-packages/airflow/operators/python.py", line 252, in execute_callable
    return self.python_callable(*self.op_args, **self.op_kwargs)
  File "/opt/airflow/dags/dags_python_fedebar.py", line 72, in main
    cache_session = requests_cache.CachedSession('.cache', expire_after = 3600)
NameError: name 'requests_cache' is not defined
[2024-05-21T01:08:18.376+0000] {taskinstance.py:1206} INFO - Marking task as FAILED. dag_id=Preentrega3-fedebar, task_id=main, run_id=scheduled__2024-05-20T20:00:00+00:00, execution_date=20240520T200000, start_date=20240521T010817, end_date=20240521T010818
[2024-05-21T01:08:18.444+0000] {standard_task_runner.py:110} ERROR - Failed to execute job 21 for task main (name 'requests_cache' is not defined; 998)
[2024-05-21T01:08:18.532+0000] {local_task_job_runner.py:240} INFO - Task exited with return code 1
[2024-05-21T01:08:18.602+0000] {taskinstance.py:3498} INFO - 0 downstream tasks scheduled from follow-on schedule check
[2024-05-21T01:08:18.631+0000] {local_task_job_runner.py:222} INFO - ::endgroup::
