[2024-05-29T15:19:12.825+0000] {local_task_job_runner.py:120} INFO - ::group::Pre task execution logs
[2024-05-29T15:19:12.846+0000] {taskinstance.py:2076} INFO - Dependencies all met for dep_context=non-requeueable deps ti=<TaskInstance: ingestion_data.redshift_connection manual__2024-05-29T15:19:01.583488+00:00 [queued]>
[2024-05-29T15:19:12.856+0000] {taskinstance.py:2076} INFO - Dependencies all met for dep_context=requeueable deps ti=<TaskInstance: ingestion_data.redshift_connection manual__2024-05-29T15:19:01.583488+00:00 [queued]>
[2024-05-29T15:19:12.858+0000] {taskinstance.py:2306} INFO - Starting attempt 1 of 2
[2024-05-29T15:19:12.874+0000] {taskinstance.py:2330} INFO - Executing <Task(PythonOperator): redshift_connection> on 2024-05-29 15:19:01.583488+00:00
[2024-05-29T15:19:12.883+0000] {standard_task_runner.py:63} INFO - Started process 490 to run task
[2024-05-29T15:19:12.886+0000] {standard_task_runner.py:90} INFO - Running: ['***', 'tasks', 'run', 'ingestion_data', 'redshift_connection', 'manual__2024-05-29T15:19:01.583488+00:00', '--job-id', '6', '--raw', '--subdir', 'DAGS_FOLDER/dag_entregable_fedebar.py', '--cfg-path', '/tmp/tmp3_y0bxjp']
[2024-05-29T15:19:12.888+0000] {standard_task_runner.py:91} INFO - Job 6: Subtask redshift_connection
[2024-05-29T15:19:12.938+0000] {task_command.py:426} INFO - Running <TaskInstance: ingestion_data.redshift_connection manual__2024-05-29T15:19:01.583488+00:00 [running]> on host 35bb4d49d405
[2024-05-29T15:19:13.017+0000] {taskinstance.py:2648} INFO - Exporting env vars: AIRFLOW_CTX_DAG_OWNER='FedeBar' AIRFLOW_CTX_DAG_ID='ingestion_data' AIRFLOW_CTX_TASK_ID='redshift_connection' AIRFLOW_CTX_EXECUTION_DATE='2024-05-29T15:19:01.583488+00:00' AIRFLOW_CTX_TRY_NUMBER='1' AIRFLOW_CTX_DAG_RUN_ID='manual__2024-05-29T15:19:01.583488+00:00'
[2024-05-29T15:19:13.018+0000] {taskinstance.py:430} INFO - ::endgroup::
[2024-05-29T15:19:13.030+0000] {logging_mixin.py:188} INFO - No es posible conectar a Redshift
[2024-05-29T15:19:13.031+0000] {taskinstance.py:441} INFO - ::group::Post task execution logs
[2024-05-29T15:19:13.032+0000] {taskinstance.py:2905} ERROR - Task failed with exception
Traceback (most recent call last):
  File "/home/airflow/.local/lib/python3.8/site-packages/airflow/models/taskinstance.py", line 465, in _execute_task
    result = _execute_callable(context=context, **execute_callable_kwargs)
  File "/home/airflow/.local/lib/python3.8/site-packages/airflow/models/taskinstance.py", line 432, in _execute_callable
    return execute_callable(context=context, **execute_callable_kwargs)
  File "/home/airflow/.local/lib/python3.8/site-packages/airflow/models/baseoperator.py", line 400, in wrapper
    return func(self, *args, **kwargs)
  File "/home/airflow/.local/lib/python3.8/site-packages/airflow/operators/python.py", line 235, in execute
    return_value = self.execute_callable()
  File "/home/airflow/.local/lib/python3.8/site-packages/airflow/operators/python.py", line 252, in execute_callable
    return self.python_callable(*self.op_args, **self.op_kwargs)
  File "/opt/airflow/dags/weather_info_ETL.py", line 28, in conectar_redshift
    with conn.cursor() as cur:
UnboundLocalError: local variable 'conn' referenced before assignment
[2024-05-29T15:19:13.047+0000] {taskinstance.py:1206} INFO - Marking task as UP_FOR_RETRY. dag_id=ingestion_data, task_id=redshift_connection, run_id=manual__2024-05-29T15:19:01.583488+00:00, execution_date=20240529T151901, start_date=20240529T151912, end_date=20240529T151913
[2024-05-29T15:19:13.064+0000] {standard_task_runner.py:110} ERROR - Failed to execute job 6 for task redshift_connection (local variable 'conn' referenced before assignment; 490)
[2024-05-29T15:19:13.100+0000] {local_task_job_runner.py:240} INFO - Task exited with return code 1
[2024-05-29T15:19:13.123+0000] {taskinstance.py:3498} INFO - 0 downstream tasks scheduled from follow-on schedule check
[2024-05-29T15:19:13.125+0000] {local_task_job_runner.py:222} INFO - ::endgroup::
