[2024-05-31T14:56:29.618+0000] {local_task_job_runner.py:120} INFO - ::group::Pre task execution logs
[2024-05-31T14:56:29.640+0000] {taskinstance.py:2076} INFO - Dependencies all met for dep_context=non-requeueable deps ti=<TaskInstance: ingestion_data.insertar_datos manual__2024-05-31T14:56:22.004938+00:00 [queued]>
[2024-05-31T14:56:29.651+0000] {taskinstance.py:2076} INFO - Dependencies all met for dep_context=requeueable deps ti=<TaskInstance: ingestion_data.insertar_datos manual__2024-05-31T14:56:22.004938+00:00 [queued]>
[2024-05-31T14:56:29.652+0000] {taskinstance.py:2306} INFO - Starting attempt 1 of 2
[2024-05-31T14:56:29.667+0000] {taskinstance.py:2330} INFO - Executing <Task(PythonOperator): insertar_datos> on 2024-05-31 14:56:22.004938+00:00
[2024-05-31T14:56:29.674+0000] {standard_task_runner.py:63} INFO - Started process 539 to run task
[2024-05-31T14:56:29.677+0000] {standard_task_runner.py:90} INFO - Running: ['***', 'tasks', 'run', 'ingestion_data', 'insertar_datos', 'manual__2024-05-31T14:56:22.004938+00:00', '--job-id', '44', '--raw', '--subdir', 'DAGS_FOLDER/dag_entregable_fedebar.py', '--cfg-path', '/tmp/tmp2krmrhis']
[2024-05-31T14:56:29.679+0000] {standard_task_runner.py:91} INFO - Job 44: Subtask insertar_datos
[2024-05-31T14:56:29.729+0000] {task_command.py:426} INFO - Running <TaskInstance: ingestion_data.insertar_datos manual__2024-05-31T14:56:22.004938+00:00 [running]> on host 167cb9f6b96a
[2024-05-31T14:56:29.810+0000] {taskinstance.py:2648} INFO - Exporting env vars: AIRFLOW_CTX_DAG_OWNER='FedeBar' AIRFLOW_CTX_DAG_ID='ingestion_data' AIRFLOW_CTX_TASK_ID='insertar_datos' AIRFLOW_CTX_EXECUTION_DATE='2024-05-31T14:56:22.004938+00:00' AIRFLOW_CTX_TRY_NUMBER='1' AIRFLOW_CTX_DAG_RUN_ID='manual__2024-05-31T14:56:22.004938+00:00'
[2024-05-31T14:56:29.811+0000] {taskinstance.py:430} INFO - ::endgroup::
[2024-05-31T14:56:29.821+0000] {base.py:84} INFO - Using connection ID 'coder-redshift-fede' for task execution.
[2024-05-31T14:56:29.822+0000] {weather_info_ETL.py:15} INFO - Conectando a Redshift en data-engineer-cluster.cyhh5bfevlmn.us-east-1.redshift.amazonaws.com:5439/data-engineer-database
[2024-05-31T14:56:31.322+0000] {warnings.py:109} WARNING - /opt/***/dags/weather_info_ETL.py:151: UserWarning: pandas only supports SQLAlchemy connectable (engine/connection) or database string URI or sqlite3 DBAPI2 connection. Other DBAPI2 objects are not tested. Please consider using SQLAlchemy.
  existing_data = pd.read_sql(query_existing_data, conn)

[2024-05-31T14:56:32.159+0000] {warnings.py:109} WARNING - /opt/***/dags/weather_info_ETL.py:155: UserWarning: pandas only supports SQLAlchemy connectable (engine/connection) or database string URI or sqlite3 DBAPI2 connection. Other DBAPI2 objects are not tested. Please consider using SQLAlchemy.
  max_existing_load_date = pd.read_sql(query_max_load_date, conn).iloc[0, 0]

[2024-05-31T14:56:32.337+0000] {taskinstance.py:441} INFO - ::group::Post task execution logs
[2024-05-31T14:56:32.338+0000] {taskinstance.py:2905} ERROR - Task failed with exception
Traceback (most recent call last):
  File "/home/airflow/.local/lib/python3.8/site-packages/airflow/models/taskinstance.py", line 465, in _execute_task
    result = _execute_callable(context=context, **execute_callable_kwargs)
  File "/home/airflow/.local/lib/python3.8/site-packages/airflow/models/taskinstance.py", line 432, in _execute_callable
    return execute_callable(context=context, **execute_callable_kwargs)
  File "/home/airflow/.local/lib/python3.8/site-packages/airflow/models/baseoperator.py", line 400, in wrapper
    return func(self, *args, **kwargs)
  File "/home/airflow/.local/lib/python3.8/site-packages/airflow/operators/python.py", line 235, in execute
    return_value = self.execute_callable()
  File "/home/airflow/.local/lib/python3.8/site-packages/airflow/operators/python.py", line 252, in execute_callable
    return self.python_callable(*self.op_args, **self.op_kwargs)
  File "/opt/airflow/dags/weather_info_ETL.py", line 157, in insertar_data
    max_daily_load_date = completed_dataframe['load_date'].max()
NameError: name 'completed_dataframe' is not defined
[2024-05-31T14:56:32.348+0000] {taskinstance.py:1206} INFO - Marking task as UP_FOR_RETRY. dag_id=ingestion_data, task_id=insertar_datos, run_id=manual__2024-05-31T14:56:22.004938+00:00, execution_date=20240531T145622, start_date=20240531T145629, end_date=20240531T145632
[2024-05-31T14:56:32.360+0000] {standard_task_runner.py:110} ERROR - Failed to execute job 44 for task insertar_datos (name 'completed_dataframe' is not defined; 539)
[2024-05-31T14:56:32.386+0000] {local_task_job_runner.py:240} INFO - Task exited with return code 1
[2024-05-31T14:56:32.401+0000] {local_task_job_runner.py:222} INFO - ::endgroup::
