[2024-05-21T01:05:07.940+0000] {local_task_job_runner.py:120} INFO - ::group::Pre task execution logs
[2024-05-21T01:05:08.239+0000] {taskinstance.py:2076} INFO - Dependencies all met for dep_context=non-requeueable deps ti=<TaskInstance: Preentrega3-fedebar.main scheduled__2024-05-20T17:00:00+00:00 [queued]>
[2024-05-21T01:05:08.345+0000] {taskinstance.py:2076} INFO - Dependencies all met for dep_context=requeueable deps ti=<TaskInstance: Preentrega3-fedebar.main scheduled__2024-05-20T17:00:00+00:00 [queued]>
[2024-05-21T01:05:08.364+0000] {taskinstance.py:2306} INFO - Starting attempt 1 of 2
[2024-05-21T01:05:08.575+0000] {taskinstance.py:2330} INFO - Executing <Task(PythonOperator): main> on 2024-05-20 17:00:00+00:00
[2024-05-21T01:05:08.667+0000] {standard_task_runner.py:63} INFO - Started process 849 to run task
[2024-05-21T01:05:08.707+0000] {standard_task_runner.py:90} INFO - Running: ['***', 'tasks', 'run', 'Preentrega3-fedebar', 'main', 'scheduled__2024-05-20T17:00:00+00:00', '--job-id', '6', '--raw', '--subdir', 'DAGS_FOLDER/dags_python_fedebar.py', '--cfg-path', '/tmp/tmp7_6ipcx2']
[2024-05-21T01:05:08.761+0000] {standard_task_runner.py:91} INFO - Job 6: Subtask main
[2024-05-21T01:05:10.098+0000] {task_command.py:426} INFO - Running <TaskInstance: Preentrega3-fedebar.main scheduled__2024-05-20T17:00:00+00:00 [running]> on host ab7b4a79fe7d
[2024-05-21T01:05:11.921+0000] {taskinstance.py:2648} INFO - Exporting env vars: AIRFLOW_CTX_DAG_OWNER='FedeBar' AIRFLOW_CTX_DAG_ID='Preentrega3-fedebar' AIRFLOW_CTX_TASK_ID='main' AIRFLOW_CTX_EXECUTION_DATE='2024-05-20T17:00:00+00:00' AIRFLOW_CTX_TRY_NUMBER='1' AIRFLOW_CTX_DAG_RUN_ID='scheduled__2024-05-20T17:00:00+00:00'
[2024-05-21T01:05:11.938+0000] {taskinstance.py:430} INFO - ::endgroup::
[2024-05-21T01:05:11.963+0000] {logging_mixin.py:188} INFO - Inicio: 2024-05-21 01:05:11.963632
[2024-05-21T01:05:11.966+0000] {taskinstance.py:441} INFO - ::group::Post task execution logs
[2024-05-21T01:05:11.970+0000] {taskinstance.py:2905} ERROR - Task failed with exception
Traceback (most recent call last):
  File "/home/airflow/.local/lib/python3.8/site-packages/airflow/models/taskinstance.py", line 465, in _execute_task
    result = _execute_callable(context=context, **execute_callable_kwargs)
  File "/home/airflow/.local/lib/python3.8/site-packages/airflow/models/taskinstance.py", line 432, in _execute_callable
    return execute_callable(context=context, **execute_callable_kwargs)
  File "/home/airflow/.local/lib/python3.8/site-packages/airflow/models/baseoperator.py", line 400, in wrapper
    return func(self, *args, **kwargs)
  File "/home/airflow/.local/lib/python3.8/site-packages/airflow/operators/python.py", line 235, in execute
    return_value = self.execute_callable()
  File "/home/airflow/.local/lib/python3.8/site-packages/airflow/operators/python.py", line 252, in execute_callable
    return self.python_callable(*self.op_args, **self.op_kwargs)
  File "/opt/airflow/dags/dags_python_fedebar.py", line 72, in main
    cache_session = requests_cache.CachedSession('.cache', expire_after = 3600)
NameError: name 'requests_cache' is not defined
[2024-05-21T01:05:12.051+0000] {taskinstance.py:1206} INFO - Marking task as UP_FOR_RETRY. dag_id=Preentrega3-fedebar, task_id=main, run_id=scheduled__2024-05-20T17:00:00+00:00, execution_date=20240520T170000, start_date=20240521T010508, end_date=20240521T010512
[2024-05-21T01:05:12.143+0000] {standard_task_runner.py:110} ERROR - Failed to execute job 6 for task main (name 'requests_cache' is not defined; 849)
[2024-05-21T01:05:12.308+0000] {local_task_job_runner.py:240} INFO - Task exited with return code 1
[2024-05-21T01:05:12.434+0000] {local_task_job_runner.py:222} INFO - ::endgroup::
