[2024-06-04T00:02:47.275+0000] {local_task_job_runner.py:120} INFO - ::group::Pre task execution logs
[2024-06-04T00:02:47.300+0000] {taskinstance.py:2076} INFO - Dependencies all met for dep_context=non-requeueable deps ti=<TaskInstance: ingestion_data.levantar_datos_API manual__2024-06-04T00:02:43.634887+00:00 [queued]>
[2024-06-04T00:02:47.309+0000] {taskinstance.py:2076} INFO - Dependencies all met for dep_context=requeueable deps ti=<TaskInstance: ingestion_data.levantar_datos_API manual__2024-06-04T00:02:43.634887+00:00 [queued]>
[2024-06-04T00:02:47.309+0000] {taskinstance.py:2306} INFO - Starting attempt 1 of 2
[2024-06-04T00:02:47.322+0000] {taskinstance.py:2330} INFO - Executing <Task(PythonOperator): levantar_datos_API> on 2024-06-04 00:02:43.634887+00:00
[2024-06-04T00:02:47.328+0000] {standard_task_runner.py:63} INFO - Started process 2313 to run task
[2024-06-04T00:02:47.332+0000] {standard_task_runner.py:90} INFO - Running: ['***', 'tasks', 'run', 'ingestion_data', 'levantar_datos_API', 'manual__2024-06-04T00:02:43.634887+00:00', '--job-id', '72', '--raw', '--subdir', 'DAGS_FOLDER/dag_entregable_fedebar.py', '--cfg-path', '/tmp/tmp1lxcug0y']
[2024-06-04T00:02:47.334+0000] {standard_task_runner.py:91} INFO - Job 72: Subtask levantar_datos_API
[2024-06-04T00:02:47.385+0000] {task_command.py:426} INFO - Running <TaskInstance: ingestion_data.levantar_datos_API manual__2024-06-04T00:02:43.634887+00:00 [running]> on host 167cb9f6b96a
[2024-06-04T00:02:47.469+0000] {taskinstance.py:2648} INFO - Exporting env vars: AIRFLOW_CTX_DAG_OWNER='FedeBar' AIRFLOW_CTX_DAG_ID='ingestion_data' AIRFLOW_CTX_TASK_ID='levantar_datos_API' AIRFLOW_CTX_EXECUTION_DATE='2024-06-04T00:02:43.634887+00:00' AIRFLOW_CTX_TRY_NUMBER='1' AIRFLOW_CTX_DAG_RUN_ID='manual__2024-06-04T00:02:43.634887+00:00'
[2024-06-04T00:02:47.471+0000] {taskinstance.py:430} INFO - ::endgroup::
[2024-06-04T00:02:48.494+0000] {taskinstance.py:441} INFO - ::group::Post task execution logs
[2024-06-04T00:02:48.496+0000] {taskinstance.py:2905} ERROR - Task failed with exception
Traceback (most recent call last):
  File "/home/airflow/.local/lib/python3.8/site-packages/airflow/models/taskinstance.py", line 465, in _execute_task
    result = _execute_callable(context=context, **execute_callable_kwargs)
  File "/home/airflow/.local/lib/python3.8/site-packages/airflow/models/taskinstance.py", line 432, in _execute_callable
    return execute_callable(context=context, **execute_callable_kwargs)
  File "/home/airflow/.local/lib/python3.8/site-packages/airflow/models/baseoperator.py", line 400, in wrapper
    return func(self, *args, **kwargs)
  File "/home/airflow/.local/lib/python3.8/site-packages/airflow/operators/python.py", line 235, in execute
    return_value = self.execute_callable()
  File "/home/airflow/.local/lib/python3.8/site-packages/airflow/operators/python.py", line 252, in execute_callable
    return self.python_callable(*self.op_args, **self.op_kwargs)
  File "/opt/airflow/dags/weather_info_ETL.py", line 101, in traer_datos_clima
    daily = response.Daily()
AttributeError: 'dict' object has no attribute 'Daily'
[2024-06-04T00:02:48.512+0000] {taskinstance.py:1206} INFO - Marking task as UP_FOR_RETRY. dag_id=ingestion_data, task_id=levantar_datos_API, run_id=manual__2024-06-04T00:02:43.634887+00:00, execution_date=20240604T000243, start_date=20240604T000247, end_date=20240604T000248
[2024-06-04T00:02:48.539+0000] {standard_task_runner.py:110} ERROR - Failed to execute job 72 for task levantar_datos_API ('dict' object has no attribute 'Daily'; 2313)
[2024-06-04T00:02:48.552+0000] {local_task_job_runner.py:240} INFO - Task exited with return code 1
[2024-06-04T00:02:48.581+0000] {taskinstance.py:3498} INFO - 0 downstream tasks scheduled from follow-on schedule check
[2024-06-04T00:02:48.584+0000] {local_task_job_runner.py:222} INFO - ::endgroup::
