[2024-05-29T21:41:36.223+0000] {local_task_job_runner.py:120} INFO - ::group::Pre task execution logs
[2024-05-29T21:41:36.241+0000] {taskinstance.py:2076} INFO - Dependencies all met for dep_context=non-requeueable deps ti=<TaskInstance: ingestion_data.insertar_datos manual__2024-05-29T21:41:27.044302+00:00 [queued]>
[2024-05-29T21:41:36.249+0000] {taskinstance.py:2076} INFO - Dependencies all met for dep_context=requeueable deps ti=<TaskInstance: ingestion_data.insertar_datos manual__2024-05-29T21:41:27.044302+00:00 [queued]>
[2024-05-29T21:41:36.250+0000] {taskinstance.py:2306} INFO - Starting attempt 1 of 2
[2024-05-29T21:41:36.263+0000] {taskinstance.py:2330} INFO - Executing <Task(PythonOperator): insertar_datos> on 2024-05-29 21:41:27.044302+00:00
[2024-05-29T21:41:36.270+0000] {standard_task_runner.py:63} INFO - Started process 1524 to run task
[2024-05-29T21:41:36.273+0000] {standard_task_runner.py:90} INFO - Running: ['***', 'tasks', 'run', 'ingestion_data', 'insertar_datos', 'manual__2024-05-29T21:41:27.044302+00:00', '--job-id', '34', '--raw', '--subdir', 'DAGS_FOLDER/dag_entregable_fedebar.py', '--cfg-path', '/tmp/tmpeq4gp42q']
[2024-05-29T21:41:36.275+0000] {standard_task_runner.py:91} INFO - Job 34: Subtask insertar_datos
[2024-05-29T21:41:36.322+0000] {task_command.py:426} INFO - Running <TaskInstance: ingestion_data.insertar_datos manual__2024-05-29T21:41:27.044302+00:00 [running]> on host 167cb9f6b96a
[2024-05-29T21:41:36.397+0000] {taskinstance.py:2648} INFO - Exporting env vars: AIRFLOW_CTX_DAG_OWNER='FedeBar' AIRFLOW_CTX_DAG_ID='ingestion_data' AIRFLOW_CTX_TASK_ID='insertar_datos' AIRFLOW_CTX_EXECUTION_DATE='2024-05-29T21:41:27.044302+00:00' AIRFLOW_CTX_TRY_NUMBER='1' AIRFLOW_CTX_DAG_RUN_ID='manual__2024-05-29T21:41:27.044302+00:00'
[2024-05-29T21:41:36.399+0000] {taskinstance.py:430} INFO - ::endgroup::
[2024-05-29T21:41:36.400+0000] {taskinstance.py:441} INFO - ::group::Post task execution logs
[2024-05-29T21:41:36.401+0000] {taskinstance.py:2905} ERROR - Task failed with exception
Traceback (most recent call last):
  File "/home/airflow/.local/lib/python3.8/site-packages/airflow/models/taskinstance.py", line 465, in _execute_task
    result = _execute_callable(context=context, **execute_callable_kwargs)
  File "/home/airflow/.local/lib/python3.8/site-packages/airflow/models/taskinstance.py", line 432, in _execute_callable
    return execute_callable(context=context, **execute_callable_kwargs)
  File "/home/airflow/.local/lib/python3.8/site-packages/airflow/models/baseoperator.py", line 400, in wrapper
    return func(self, *args, **kwargs)
  File "/home/airflow/.local/lib/python3.8/site-packages/airflow/operators/python.py", line 235, in execute
    return_value = self.execute_callable()
  File "/home/airflow/.local/lib/python3.8/site-packages/airflow/operators/python.py", line 252, in execute_callable
    return self.python_callable(*self.op_args, **self.op_kwargs)
  File "/opt/airflow/dags/weather_info_ETL.py", line 145, in insertar_data
    existing_data = pd.read_sql(query_existing_data, conn)
NameError: name 'conn' is not defined
[2024-05-29T21:41:36.415+0000] {taskinstance.py:1206} INFO - Marking task as UP_FOR_RETRY. dag_id=ingestion_data, task_id=insertar_datos, run_id=manual__2024-05-29T21:41:27.044302+00:00, execution_date=20240529T214127, start_date=20240529T214136, end_date=20240529T214136
[2024-05-29T21:41:36.427+0000] {standard_task_runner.py:110} ERROR - Failed to execute job 34 for task insertar_datos (name 'conn' is not defined; 1524)
[2024-05-29T21:41:36.447+0000] {local_task_job_runner.py:240} INFO - Task exited with return code 1
[2024-05-29T21:41:36.460+0000] {taskinstance.py:3498} INFO - 0 downstream tasks scheduled from follow-on schedule check
[2024-05-29T21:41:36.463+0000] {local_task_job_runner.py:222} INFO - ::endgroup::
