[2024-05-29T21:44:38.361+0000] {local_task_job_runner.py:120} INFO - ::group::Pre task execution logs
[2024-05-29T21:44:38.408+0000] {taskinstance.py:2076} INFO - Dependencies all met for dep_context=non-requeueable deps ti=<TaskInstance: ingestion_data.insertar_datos manual__2024-05-29T21:41:27.044302+00:00 [queued]>
[2024-05-29T21:44:38.418+0000] {taskinstance.py:2076} INFO - Dependencies all met for dep_context=requeueable deps ti=<TaskInstance: ingestion_data.insertar_datos manual__2024-05-29T21:41:27.044302+00:00 [queued]>
[2024-05-29T21:44:38.419+0000] {taskinstance.py:2306} INFO - Starting attempt 2 of 2
[2024-05-29T21:44:38.432+0000] {taskinstance.py:2330} INFO - Executing <Task(PythonOperator): insertar_datos> on 2024-05-29 21:41:27.044302+00:00
[2024-05-29T21:44:38.441+0000] {standard_task_runner.py:63} INFO - Started process 1641 to run task
[2024-05-29T21:44:38.445+0000] {standard_task_runner.py:90} INFO - Running: ['***', 'tasks', 'run', 'ingestion_data', 'insertar_datos', 'manual__2024-05-29T21:41:27.044302+00:00', '--job-id', '35', '--raw', '--subdir', 'DAGS_FOLDER/dag_entregable_fedebar.py', '--cfg-path', '/tmp/tmplg6nakcu']
[2024-05-29T21:44:38.446+0000] {standard_task_runner.py:91} INFO - Job 35: Subtask insertar_datos
[2024-05-29T21:44:38.506+0000] {task_command.py:426} INFO - Running <TaskInstance: ingestion_data.insertar_datos manual__2024-05-29T21:41:27.044302+00:00 [running]> on host 167cb9f6b96a
[2024-05-29T21:44:38.599+0000] {taskinstance.py:2648} INFO - Exporting env vars: AIRFLOW_CTX_DAG_OWNER='FedeBar' AIRFLOW_CTX_DAG_ID='ingestion_data' AIRFLOW_CTX_TASK_ID='insertar_datos' AIRFLOW_CTX_EXECUTION_DATE='2024-05-29T21:41:27.044302+00:00' AIRFLOW_CTX_TRY_NUMBER='2' AIRFLOW_CTX_DAG_RUN_ID='manual__2024-05-29T21:41:27.044302+00:00'
[2024-05-29T21:44:38.601+0000] {taskinstance.py:430} INFO - ::endgroup::
[2024-05-29T21:44:38.602+0000] {taskinstance.py:441} INFO - ::group::Post task execution logs
[2024-05-29T21:44:38.603+0000] {taskinstance.py:2905} ERROR - Task failed with exception
Traceback (most recent call last):
  File "/home/airflow/.local/lib/python3.8/site-packages/airflow/models/taskinstance.py", line 465, in _execute_task
    result = _execute_callable(context=context, **execute_callable_kwargs)
  File "/home/airflow/.local/lib/python3.8/site-packages/airflow/models/taskinstance.py", line 432, in _execute_callable
    return execute_callable(context=context, **execute_callable_kwargs)
  File "/home/airflow/.local/lib/python3.8/site-packages/airflow/models/baseoperator.py", line 400, in wrapper
    return func(self, *args, **kwargs)
  File "/home/airflow/.local/lib/python3.8/site-packages/airflow/operators/python.py", line 235, in execute
    return_value = self.execute_callable()
  File "/home/airflow/.local/lib/python3.8/site-packages/airflow/operators/python.py", line 252, in execute_callable
    return self.python_callable(*self.op_args, **self.op_kwargs)
  File "/opt/airflow/dags/weather_info_ETL.py", line 145, in insertar_data
    existing_data = pd.read_sql(query_existing_data, conn)
NameError: name 'conn' is not defined
[2024-05-29T21:44:38.620+0000] {taskinstance.py:1206} INFO - Marking task as FAILED. dag_id=ingestion_data, task_id=insertar_datos, run_id=manual__2024-05-29T21:41:27.044302+00:00, execution_date=20240529T214127, start_date=20240529T214438, end_date=20240529T214438
[2024-05-29T21:44:38.634+0000] {standard_task_runner.py:110} ERROR - Failed to execute job 35 for task insertar_datos (name 'conn' is not defined; 1641)
[2024-05-29T21:44:38.658+0000] {local_task_job_runner.py:240} INFO - Task exited with return code 1
[2024-05-29T21:44:38.675+0000] {taskinstance.py:3498} INFO - 0 downstream tasks scheduled from follow-on schedule check
[2024-05-29T21:44:38.679+0000] {local_task_job_runner.py:222} INFO - ::endgroup::
